Workbook

Sheet README
B2: Andean FX System v1 — Feature Specification (CLP, COP, PEN)
B3: Universe: USD/CLP, USD/COP, USD/PEN (offshore NDF + onshore reference) · Frequencies: 1h, 1d · Horizons: 1h to 20d
B5: Purpose | C5: Engineering spec for every model input for an Andean FX system (USD/CLP, USD/COP, USD/PEN): definition, source, frequency, lookback, transformation, availability time, leakage rule and which models consume it.
B6: What changed vs the BRL/MXN version | C6: Added PEN. Dropped the order-book microstructure block and the intraday TCN/Mamba model (no deep public order book in these markets). Added BCRP intervention, COP offshore NDF positioning, CLP/COP/PEN pension-fund (AFP) flows, Peru pension-withdrawal events, fixing deviation, onshore/offshore session split, and a political-risk block. Regime model cut to 5 states.
B7: Tabs | C7: Summary · Feature Spec · Targets · Models · Currency Notes · Data Sources · Stress Episodes · Roadmap
B8: Feature count | C8: Each row is a feature family. 'Variants per ccy' × '# Ccys' = model columns it generates. Summary tab totals these; edit variants (blue) to resize the set.
B9: Timestamp convention | C9: Store everything in UTC with event time (what the value describes) and availability time (when you could first have used it). Every join uses availability time. Keep first-release vintages.
B10: Decision convention | C10: One daily decision snapshot late in the Andean onshore sessions (default 12:30 New York; configurable). Signals use data available before the snapshot; trades execute after it.
B11: Leakage rules | C11: Releases usable only from publication time + buffer; revised data never used in backtests; HMM uses filtered probabilities; scalers, betas, PCA, cointegration and NLP models fit on training windows only.
B12: Priority | C12: P1 = build first · P2 = second wave · P3 = only if it survives the incremental-alpha test
B13: Model codes | C13: PAT = PatchTST (hourly, pooled with helper ccys) · TFT = Temporal Fusion Transformer (daily) · XGB = LightGBM/XGBoost · HMM = regime model · EXE = execution scheduler (timing vs local session/fixings, dealer quotes)
B14: Editable inputs | C14: Blue text = hardcoded inputs you can change (variants per ccy, cost estimates). Black = formulas.
B15: Caveat | C15: Series names, publication times, lags and cost figures are best estimates. Verify each against the current central-bank releases and your dealers before production. BCRP instrument names in particular change over time.

Sheet Summary
A1: Feature set summary
A2: All figures are formulas over the Feature Spec tab.
A4: Feature families | B4: =COUNTA('Feature Spec'!$A$2:$A$80) -> 79
A5: Total model columns | B5: =SUM('Feature Spec'!$H$2:$H$80) -> 393
A7: Block | B7: Families | C7: Columns | D7: % of columns
A8: PX Price & returns | B8: =COUNTIF('Feature Spec'!$B$2:$B$80,A8) -> 9 | C8: =SUMIF('Feature Spec'!$B$2:$B$80,A8,'Feature Spec'!$H$2:$H$80) -> 75 | D8: =IF($B$5=0,0,C8/$B$5) -> 0.19083969
A9: CR Carry & forwards | B9: =COUNTIF('Feature Spec'!$B$2:$B$80,A9) -> 6 | C9: =SUMIF('Feature Spec'!$B$2:$B$80,A9,'Feature Spec'!$H$2:$H$80) -> 30 | D9: =IF($B$5=0,0,C9/$B$5) -> 0.076335878
A10: RT Local rates | B10: =COUNTIF('Feature Spec'!$B$2:$B$80,A10) -> 7 | C10: =SUMIF('Feature Spec'!$B$2:$B$80,A10,'Feature Spec'!$H$2:$H$80) -> 37 | D10: =IF($B$5=0,0,C10/$B$5) -> 0.094147583
A11: VS Options & vol | B11: =COUNTIF('Feature Spec'!$B$2:$B$80,A11) -> 4 | C11: =SUMIF('Feature Spec'!$B$2:$B$80,A11,'Feature Spec'!$H$2:$H$80) -> 16 | D11: =IF($B$5=0,0,C11/$B$5) -> 0.040712468
A12: PF Positioning & flows | B12: =COUNTIF('Feature Spec'!$B$2:$B$80,A12) -> 8 | C12: =SUMIF('Feature Spec'!$B$2:$B$80,A12,'Feature Spec'!$H$2:$H$80) -> 28 | D12: =IF($B$5=0,0,C12/$B$5) -> 0.071246819
A13: CB Central bank & intervention | B13: =COUNTIF('Feature Spec'!$B$2:$B$80,A13) -> 8 | C13: =SUMIF('Feature Spec'!$B$2:$B$80,A13,'Feature Spec'!$H$2:$H$80) -> 20 | D13: =IF($B$5=0,0,C13/$B$5) -> 0.050890585
A14: MA Macro surprises | B14: =COUNTIF('Feature Spec'!$B$2:$B$80,A14) -> 5 | C14: =SUMIF('Feature Spec'!$B$2:$B$80,A14,'Feature Spec'!$H$2:$H$80) -> 26 | D14: =IF($B$5=0,0,C14/$B$5) -> 0.066157761
A15: CM Commodities | B15: =COUNTIF('Feature Spec'!$B$2:$B$80,A15) -> 4 | C15: =SUMIF('Feature Spec'!$B$2:$B$80,A15,'Feature Spec'!$H$2:$H$80) -> 21 | D15: =IF($B$5=0,0,C15/$B$5) -> 0.053435115
A16: GL Global risk & USD | B16: =COUNTIF('Feature Spec'!$B$2:$B$80,A16) -> 6 | C16: =SUMIF('Feature Spec'!$B$2:$B$80,A16,'Feature Spec'!$H$2:$H$80) -> 18 | D16: =IF($B$5=0,0,C16/$B$5) -> 0.045801527
A17: XS Cross-sectional & RV | B17: =COUNTIF('Feature Spec'!$B$2:$B$80,A17) -> 4 | C17: =SUMIF('Feature Spec'!$B$2:$B$80,A17,'Feature Spec'!$H$2:$H$80) -> 27 | D17: =IF($B$5=0,0,C17/$B$5) -> 0.06870229
A18: VL Value & fundamentals | B18: =COUNTIF('Feature Spec'!$B$2:$B$80,A18) -> 2 | C18: =SUMIF('Feature Spec'!$B$2:$B$80,A18,'Feature Spec'!$H$2:$H$80) -> 6 | D18: =IF($B$5=0,0,C18/$B$5) -> 0.015267176
A19: CAL Calendar & seasonality | B19: =COUNTIF('Feature Spec'!$B$2:$B$80,A19) -> 5 | C19: =SUMIF('Feature Spec'!$B$2:$B$80,A19,'Feature Spec'!$H$2:$H$80) -> 27 | D19: =IF($B$5=0,0,C19/$B$5) -> 0.06870229
... A22: RG Regime & meta | B22: =COUNTIF('Feature Spec'!$B$2:$B$80,A22) -> 4 | C22: =SUMIF('Feature Spec'!$B$2:$B$80,A22,'Feature Spec'!$H$2:$H$80) -> 23 | D22: =IF($B$5=0,0,C22/$B$5) -> 0.058524173
A23: Total | B23: =SUM(B8:B22) -> 79 | C23: =SUM(C8:C22) -> 393 | D23: =SUM(D8:D22) -> 1
A26: Priority | B26: Families | C26: Columns | D26: % of columns
A27: P1 | B27: =COUNTIF('Feature Spec'!$U$2:$U$80,A27) -> 45 | C27: =SUMIF('Feature Spec'!$U$2:$U$80,A27,'Feature Spec'!$H$2:$H$80) -> 258 | D27: =IF($B$5=0,0,C27/$B$5) -> 0.65648855
A28: P2 | B28: =COUNTIF('Feature Spec'!$U$2:$U$80,A28) -> 24 | C28: =SUMIF('Feature Spec'!$U$2:$U$80,A28,'Feature Spec'!$H$2:$H$80) -> 92 | D28: =IF($B$5=0,0,C28/$B$5) -> 0.23409669
A29: P3 | B29: =COUNTIF('Feature Spec'!$U$2:$U$80,A29) -> 10 | C29: =SUMIF('Feature Spec'!$U$2:$U$80,A29,'Feature Spec'!$H$2:$H$80) -> 43 | D29: =IF($B$5=0,0,C29/$B$5) -> 0.10941476
A32: Model | B32: Families used | C32: Columns used | D32: % of columns
A33: PatchTST (hourly) | B33: =SUM('Feature Spec'!$P$2:$P$80) -> 10 | C33: =SUMPRODUCT('Feature Spec'!$P$2:$P$80,'Feature Spec'!$H$2:$H$80) -> 73 | D33: =IF($B$5=0,0,C33/$B$5) -> 0.18575064
A34: TFT (daily) | B34: =SUM('Feature Spec'!$Q$2:$Q$80) -> 63 | C34: =SUMPRODUCT('Feature Spec'!$Q$2:$Q$80,'Feature Spec'!$H$2:$H$80) -> 320 | D34: =IF($B$5=0,0,C34/$B$5) -> 0.81424936
A35: LightGBM / XGBoost | B35: =SUM('Feature Spec'!$R$2:$R$80) -> 77 | C35: =SUMPRODUCT('Feature Spec'!$R$2:$R$80,'Feature Spec'!$H$2:$H$80) -> 380 | D35: =IF($B$5=0,0,C35/$B$5) -> 0.96692112
A36: HMM regime | B36: =SUM('Feature Spec'!$S$2:$S$80) -> 14 | C36: =SUMPRODUCT('Feature Spec'!$S$2:$S$80,'Feature Spec'!$H$2:$H$80) -> 68 | D36: =IF($B$5=0,0,C36/$B$5) -> 0.17302799
A37: Execution scheduler | B37: =SUM('Feature Spec'!$T$2:$T$80) -> 6 | C37: =SUMPRODUCT('Feature Spec'!$T$2:$T$80,'Feature Spec'!$H$2:$H$80) -> 24 | D37: =IF($B$5=0,0,C37/$B$5) -> 0.061068702
A39: Sample-size check: ~15y of daily data × 3 ccys ≈ 11k correlated rows. Daily models (TFT, XGB) should see a pruned subset (target < 100 columns after feature selection); intraday models get the high-frequency blocks.

Sheet Feature Spec
A1: ID | B1: Block | C1: Feature | D1: Definition / formula | E1: Currencies | F1: # Ccys | G1: Variants per ccy | H1: Total columns | I1: Source | J1: Native freq | K1: Model freq | L1: Lookbacks / params | M1: Transformation | N1: Availability / publication lag | O1: Leakage rule | P1: PAT | Q1: TFT | R1: XGB | S1: HMM | T1: EXE | U1: Priority | V1: Notes
A2: PX-01 | B2: PX Price & returns | C2: Log return | D2: ln(S_t / S_{t-k}) on onshore spot in local session, NDF 1M mid otherwise | E2: ALL | F2: =IF(E2="ALL",3,IF(E2="Global",1,LEN(E2)-LEN(SUBSTITUTE(E2,",",""))+1)) -> 3 | G2: 6 | H2: =F2*G2 -> 18 | I2: Datatec (CLP, PEN), SET-FX (COP), dealer NDF quotes | J2: 1h | K2: 1h,1d | L2: k = 1, 4 (1h); 1, 5, 20 (1d); session return | M2: Winsorize 5 sigma | N2: Real time | O2: Compute on bars closed at or before t; trade from bar t+1. | P2: 1 | Q2: 1 | R2: 1 | S2: 0 | T2: 0 | U2: P1 | V2: Build one continuous series: onshore spot when open, NDF-implied spot otherwise; flag the source
A3: PX-02 | B3: PX Price & returns | C3: Vol-scaled momentum | D3: r_{t-k,t} / (sigma_k * sqrt(k)) | E3: ALL | F3: =IF(E3="ALL",3,IF(E3="Global",1,LEN(E3)-LEN(SUBSTITUTE(E3,",",""))+1)) -> 3 | G3: 4 | H3: =F3*G3 -> 12 | I3: Derived | J3: 1d | K3: 1d | L3: k = 5, 20, 60, 120 d | M3: Clip +/-4 | N3: Snapshot | O3: Value as of the daily decision snapshot; if source updates after it, use prior snapshot. | P3: 0 | Q3: 1 | R3: 1 | S3: 0 | T3: 0 | U3: P1 | V3: Core factor
A4: PX-03 | B4: PX Price & returns | C4: Realized volatility | D4: Annualized RV from hourly (or daily) returns | E4: ALL | F4: =IF(E4="ALL",3,IF(E4="Global",1,LEN(E4)-LEN(SUBSTITUTE(E4,",",""))+1)) -> 3 | G4: 3 | H4: =F4*G4 -> 9 | I4: Derived | J4: 1h | K4: 1d | L4: 5d, 20d, 60d | M4: log | N4: Snapshot | O4: Value as of the daily decision snapshot; if source updates after it, use prior snapshot. | P4: 1 | Q4: 1 | R4: 1 | S4: 1 | T4: 0 | U4: P1 | V4: PEN RV is suppressed by BCRP; compare to implied vol
A5: PX-04 | B5: PX Price & returns | C5: Range volatility | D5: Garman-Klass on onshore OHLC | E5: ALL | F5: =IF(E5="ALL",3,IF(E5="Global",1,LEN(E5)-LEN(SUBSTITUTE(E5,",",""))+1)) -> 3 | G5: 2 | H5: =F5*G5 -> 6 | I5: Onshore OHLC | J5: 1d | K5: 1d | L5: 5d, 20d | M5: log | N5: After onshore close | O5: Value as of the daily decision snapshot; if source updates after it, use prior snapshot. | P5: 0 | Q5: 1 | R5: 1 | S5: 0 | T5: 0 | U5: P2 | V5: Robust to thin intraday data
A6: PX-05 | B6: PX Price & returns | C6: Jump indicator | D6: |r_d| > 3 sigma_60d flag and count over window | E6: ALL | F6: =IF(E6="ALL",3,IF(E6="Global",1,LEN(E6)-LEN(SUBSTITUTE(E6,",",""))+1)) -> 3 | G6: 2 | H6: =F6*G6 -> 6 | I6: Derived | J6: 1d | K6: 1d | L6: Flag; 60d count | M6: None | N6: Snapshot | O6: Value as of the daily decision snapshot; if source updates after it, use prior snapshot. | P6: 0 | Q6: 0 | R6: 1 | S6: 1 | T6: 0 | U6: P2 | V6: Captures gap risk hidden by smoothing (esp. PEN)
A7: PX-06 | B7: PX Price & returns | C7: Distance from moving average | D7: (S_t - MA_k) / sigma_20d | E7: ALL | F7: =IF(E7="ALL",3,IF(E7="Global",1,LEN(E7)-LEN(SUBSTITUTE(E7,",",""))+1)) -> 3 | G7: 3 | H7: =F7*G7 -> 9 | I7: Derived | J7: 1d | K7: 1d | L7: k = 20, 50, 200 d | M7: None | N7: Snapshot | O7: Value as of the daily decision snapshot; if source updates after it, use prior snapshot. | P7: 0 | Q7: 1 | R7: 1 | S7: 0 | T7: 0 | U7: P2
A8: PX-07 | B8: PX Price & returns | C8: Range position | D8: (S_t - min_N) / (max_N - min_N) | E8: ALL | F8: =IF(E8="ALL",3,IF(E8="Global",1,LEN(E8)-LEN(SUBSTITUTE(E8,",",""))+1)) -> 3 | G8: 2 | H8: =F8*G8 -> 6 | I8: Derived | J8: 1d | K8: 1d | L8: N = 20, 60 d | M8: None | N8: Snapshot | O8: Value as of the daily decision snapshot; if source updates after it, use prior snapshot. | P8: 0 | Q8: 0 | R8: 1 | S8: 0 | T8: 0 | U8: P3 | V8: Breakout signal
A9: PX-08 | B9: PX Price & returns | C9: Onshore vs offshore session return | D9: Onshore-session return vs overnight NDF-implied move | E9: ALL | F9: =IF(E9="ALL",3,IF(E9="Global",1,LEN(E9)-LEN(SUBSTITUTE(E9,",",""))+1)) -> 3 | G9: 2 | H9: =F9*G9 -> 6 | I9: Onshore spot + NDF | J9: 1h | K9: 1d | L9: 1d; 5d sum | M9: None | N9: After onshore close | O9: Value as of the daily decision snapshot; if source updates after it, use prior snapshot. | P9: 0 | Q9: 1 | R9: 1 | S9: 0 | T9: 0 | U9: P1 | V9: Offshore pressure vs local flow; key for all three NDF markets
A10: PX-09 | B10: PX Price & returns | C10: Fixing deviation | D10: Spot at snapshot - official fix (dólar observado / TRM / BCRP ref. rate), in bps | E10: ALL | F10: =IF(E10="ALL",3,IF(E10="Global",1,LEN(E10)-LEN(SUBSTITUTE(E10,",",""))+1)) -> 3 | G10: 1 | H10: =F10*G10 -> 3 | I10: BCCh, BanRep/Superfinanciera, BCRP | J10: 1d | K10: 1d | L10: Level; 5d mean | M10: z-score | N10: Fix published per CB rules | O10: Usable only from actual publication timestamp + buffer; never align to reference date. | P10: 0 | Q10: 0 | R10: 1 | S10: 0 | T10: 1 | U10: P2 | V10: CLP dólar observado and COP TRM are set from the prior day's trades
A11: CR-01 | B11: CR Carry & forwards | C11: NDF-implied yield | D11: i_loc = ((F/S)*(1 + i_usd*tau) - 1)/tau from offshore NDF curve | E11: ALL | F11: =IF(E11="ALL",3,IF(E11="Global",1,LEN(E11)-LEN(SUBSTITUTE(E11,",",""))+1)) -> 3 | G11: 3 | H11: =F11*G11 -> 9 | I11: Dealer NDF quotes / Bloomberg | J11: 1d | K11: 1d | L11: 1M, 3M, 12M | M11: None | N11: Snapshot | O11: Value as of the daily decision snapshot; if source updates after it, use prior snapshot. | P11: 0 | Q11: 1 | R11: 1 | S11: 0 | T11: 0 | U11: P1
A12: CR-02 | B12: CR Carry & forwards | C12: Carry | D12: i_loc(3M) - SOFR(3M) | E12: ALL | F12: =IF(E12="ALL",3,IF(E12="Global",1,LEN(E12)-LEN(SUBSTITUTE(E12,",",""))+1)) -> 3 | G12: 1 | H12: =F12*G12 -> 3 | I12: Derived | J12: 1d | K12: 1d | L12: 3M | M12: None | N12: Snapshot | O12: Value as of the daily decision snapshot; if source updates after it, use prior snapshot. | P12: 0 | Q12: 1 | R12: 1 | S12: 0 | T12: 0 | U12: P1 | V12: Core factor
A13: CR-03 | B13: CR Carry & forwards | C13: Carry-to-vol | D13: Carry / 3M implied vol (realized vol where options too thin, e.g. PEN) | E13: ALL | F13: =IF(E13="ALL",3,IF(E13="Global",1,LEN(E13)-LEN(SUBSTITUTE(E13,",",""))+1)) -> 3 | G13: 1 | H13: =F13*G13 -> 3 | I13: Derived | J13: 1d | K13: 1d | L13: 3M | M13: Cross-sectional rank also | N13: Snapshot | O13: Value as of the daily decision snapshot; if source updates after it, use prior snapshot. | P13: 0 | Q13: 1 | R13: 1 | S13: 0 | T13: 0 | U13: P1
A14: CR-04 | B14: CR Carry & forwards | C14: Onshore-offshore basis | D14: Onshore forward-implied yield minus offshore NDF-implied yield | E14: ALL | F14: =IF(E14="ALL",3,IF(E14="Global",1,LEN(E14)-LEN(SUBSTITUTE(E14,",",""))+1)) -> 3 | G14: 2 | H14: =F14*G14 -> 6 | I14: Local dealer fwd quotes, NDF quotes | J14: 1d | K14: 1d | L14: Level; 5d change | M14: z-score vs 1y | N14: Snapshot | O14: Value as of the daily decision snapshot; if source updates after it, use prior snapshot. | P14: 0 | Q14: 1 | R14: 1 | S14: 0 | T14: 0 | U14: P1 | V14: Dollar scarcity / convertibility stress; onshore quotes may need a local dealer
A15: CR-05 | B15: CR Carry & forwards | C15: Change in implied yield | D15: Delta i_loc(3M) | E15: ALL | F15: =IF(E15="ALL",3,IF(E15="Global",1,LEN(E15)-LEN(SUBSTITUTE(E15,",",""))+1)) -> 3 | G15: 2 | H15: =F15*G15 -> 6 | I15: Derived | J15: 1d | K15: 1d | L15: 5d, 20d | M15: None | N15: Snapshot | O15: Value as of the daily decision snapshot; if source updates after it, use prior snapshot. | P15: 0 | Q15: 1 | R15: 1 | S15: 0 | T15: 0 | U15: P2
A16: CR-06 | B16: CR Carry & forwards | C16: Forward curve slope | D16: i_loc(12M) - i_loc(1M) | E16: ALL | F16: =IF(E16="ALL",3,IF(E16="Global",1,LEN(E16)-LEN(SUBSTITUTE(E16,",",""))+1)) -> 3 | G16: 1 | H16: =F16*G16 -> 3 | I16: Derived | J16: 1d | K16: 1d | M16: None | N16: Snapshot | O16: Value as of the daily decision snapshot; if source updates after it, use prior snapshot. | P16: 0 | Q16: 0 | R16: 1 | S16: 0 | T16: 0 | U16: P3
A17: RT-01 | B17: RT Local rates | C17: Local curve levels | D17: CLP: cámara swap; COP: IBR OIS / TES; PEN: BCRP interbank / sovereign bonds (soberanos) | E17: ALL | F17: =IF(E17="ALL",3,IF(E17="Global",1,LEN(E17)-LEN(SUBSTITUTE(E17,",",""))+1)) -> 3 | G17: 3 | H17: =F17*G17 -> 9 | I17: Broker screens, Bloomberg, CB statistics | J17: 1d | K17: 1d | L17: 1y, 2y, 5y | M17: Daily change also | N17: Daily close | O17: Value as of the daily decision snapshot; if source updates after it, use prior snapshot. | P17: 0 | Q17: 1 | R17: 1 | S17: 0 | T17: 0 | U17: P1 | V17: PEN swap curve thin: use sovereign bond yields
A18: RT-02 | B18: RT Local rates | C18: Rate differential vs US | D18: Local 2y - UST 2y | E18: ALL | F18: =IF(E18="ALL",3,IF(E18="Global",1,LEN(E18)-LEN(SUBSTITUTE(E18,",",""))+1)) -> 3 | G18: 2 | H18: =F18*G18 -> 6 | I18: Derived | J18: 1d | K18: 1d | L18: Level; 20d change | M18: None | N18: Daily close | O18: Value as of the daily decision snapshot; if source updates after it, use prior snapshot. | P18: 0 | Q18: 1 | R18: 1 | S18: 0 | T18: 0 | U18: P1
A19: RT-03 | B19: RT Local rates | C19: Curve slope | D19: 5y - 1y local | E19: ALL | F19: =IF(E19="ALL",3,IF(E19="Global",1,LEN(E19)-LEN(SUBSTITUTE(E19,",",""))+1)) -> 3 | G19: 1 | H19: =F19*G19 -> 3 | I19: Derived | J19: 1d | K19: 1d | M19: None | N19: Daily close | O19: Value as of the daily decision snapshot; if source updates after it, use prior snapshot. | P19: 0 | Q19: 1 | R19: 1 | S19: 0 | T19: 0 | U19: P2 | V19: COP steepening = fiscal stress
A20: RT-04 | B20: RT Local rates | C20: Policy path priced | D20: Implied rate at next 2 meetings - current policy rate | E20: CLP, COP | F20: =IF(E20="ALL",3,IF(E20="Global",1,LEN(E20)-LEN(SUBSTITUTE(E20,",",""))+1)) -> 2 | G20: 2 | H20: =F20*G20 -> 4 | I20: Derived from swap curve | J20: 1d | K20: 1d | L20: Next meeting; 6M | M20: None | N20: Daily close | O20: Value as of the daily decision snapshot; if source updates after it, use prior snapshot. | P20: 0 | Q20: 1 | R20: 1 | S20: 0 | T20: 0 | U20: P1 | V20: PEN: use analyst survey instead (thin curve)
A21: RT-05 | B21: RT Local rates | C21: Real policy rate | D21: Policy rate - 12m inflation expectation | E21: ALL | F21: =IF(E21="ALL",3,IF(E21="Global",1,LEN(E21)-LEN(SUBSTITUTE(E21,",",""))+1)) -> 3 | G21: 1 | H21: =F21*G21 -> 3 | I21: BCCh EEE, BanRep survey, BCRP expectations survey | J21: Monthly | K21: 1d | M21: Forward-fill | N21: On survey release | O21: Usable only from actual publication timestamp + buffer; never align to reference date. | P21: 0 | Q21: 1 | R21: 1 | S21: 0 | T21: 0 | U21: P2
A22: RT-06 | B22: RT Local rates | C22: Sovereign CDS | D22: 5y USD CDS level and change | E22: ALL | F22: =IF(E22="ALL",3,IF(E22="Global",1,LEN(E22)-LEN(SUBSTITUTE(E22,",",""))+1)) -> 3 | G22: 2 | H22: =F22*G22 -> 6 | I22: Markit / Bloomberg | J22: 1d | K22: 1d | L22: Level; 5d change | M22: log | N22: EOD, often next morning | O22: Lag 1 day unless intraday feed | P22: 0 | Q22: 1 | R22: 1 | S22: 1 | T22: 0 | U22: P1
A23: RT-07 | B23: RT Local rates | C23: Local bond foreign holdings | D23: Non-resident holdings of TES (COP), soberanos (PEN), BTP/BTU (CLP) | E23: ALL | F23: =IF(E23="ALL",3,IF(E23="Global",1,LEN(E23)-LEN(SUBSTITUTE(E23,",",""))+1)) -> 3 | G23: 2 | H23: =F23*G23 -> 6 | I23: MinHacienda/BanRep, BCRP/MEF, BCCh/DCV | J23: Weekly/Monthly | K23: 1d | L23: Level % of stock; 4w change | M23: z-score | N23: Published with lag (verify per source) | O23: Usable only from actual publication timestamp + buffer; never align to reference date. | P23: 0 | Q23: 1 | R23: 1 | S23: 0 | T23: 0 | U23: P2 | V23: Big driver in COP and PEN selloffs
A24: VS-01 | B24: VS Options & vol | C24: ATM implied vol | D24: ATM vol by tenor | E24: CLP, COP | F24: =IF(E24="ALL",3,IF(E24="Global",1,LEN(E24)-LEN(SUBSTITUTE(E24,",",""))+1)) -> 2 | G24: 3 | H24: =F24*G24 -> 6 | I24: Dealer / Bloomberg vol surface | J24: 1d | K24: 1d | L24: 1M, 3M, 1Y | M24: log | N24: Snapshot | O24: Value as of the daily decision snapshot; if source updates after it, use prior snapshot. | P24: 0 | Q24: 1 | R24: 1 | S24: 1 | T24: 0 | U24: P1 | V24: PEN options very thin; use realized vol + BCRP intervention intensity instead
A25: VS-02 | B25: VS Options & vol | C25: 25d risk reversal | D25: 25-delta USD call vol - put vol | E25: CLP, COP | F25: =IF(E25="ALL",3,IF(E25="Global",1,LEN(E25)-LEN(SUBSTITUTE(E25,",",""))+1)) -> 2 | G25: 3 | H25: =F25*G25 -> 6 | I25: Vol surface | J25: 1d | K25: 1d | L25: 1M level; 1d, 5d change | M25: z-score vs 1y | N25: Snapshot | O25: Value as of the daily decision snapshot; if source updates after it, use prior snapshot. | P25: 0 | Q25: 1 | R25: 1 | S25: 1 | T25: 0 | U25: P1 | V25: Leading fear gauge
A26: VS-03 | B26: VS Options & vol | C26: Vol term slope | D26: 1M - 3M ATM vol | E26: CLP, COP | F26: =IF(E26="ALL",3,IF(E26="Global",1,LEN(E26)-LEN(SUBSTITUTE(E26,",",""))+1)) -> 2 | G26: 1 | H26: =F26*G26 -> 2 | I26: Derived | J26: 1d | K26: 1d | M26: None | N26: Snapshot | O26: Value as of the daily decision snapshot; if source updates after it, use prior snapshot. | P26: 0 | Q26: 0 | R26: 1 | S26: 1 | T26: 0 | U26: P2 | V26: Inversion = stress
A27: VS-04 | B27: VS Options & vol | C27: Variance risk premium | D27: ATM IV 1M - RV 20d | E27: CLP, COP | F27: =IF(E27="ALL",3,IF(E27="Global",1,LEN(E27)-LEN(SUBSTITUTE(E27,",",""))+1)) -> 2 | G27: 1 | H27: =F27*G27 -> 2 | I27: Derived | J27: 1d | K27: 1d | M27: None | N27: Snapshot | O27: Value as of the daily decision snapshot; if source updates after it, use prior snapshot. | P27: 0 | Q27: 1 | R27: 1 | S27: 0 | T27: 0 | U27: P2
A28: PF-01 | B28: PF Positioning & flows | C28: CLP pension fund FX forwards | D28: AFP net forward USD sales (hedge ratio) and change | E28: CLP | F28: =IF(E28="ALL",3,IF(E28="Global",1,LEN(E28)-LEN(SUBSTITUTE(E28,",",""))+1)) -> 1 | G28: 3 | H28: =F28*G28 -> 3 | I28: BCCh statistics / Superintendencia de Pensiones | J28: Weekly/Monthly | K28: 1d | L28: Level; 4w change; % of FX assets | M28: z-score vs 3y | N28: On release (verify cadence and lag) | O28: Usable only from actual publication timestamp + buffer; never align to reference date. | P28: 0 | Q28: 1 | R28: 1 | S28: 0 | T28: 0 | U28: P1 | V28: AFP hedging shifts are large vs market depth; also watch multifund switching
A29: PF-02 | B29: PF Positioning & flows | C29: COP offshore NDF positioning | D29: Offshore agents' net forward USD purchases/sales with local banks | E29: COP | F29: =IF(E29="ALL",3,IF(E29="Global",1,LEN(E29)-LEN(SUBSTITUTE(E29,",",""))+1)) -> 1 | G29: 3 | H29: =F29*G29 -> 3 | I29: BanRep derivatives statistics | J29: Weekly | K29: 1d | L29: Level z; 1w, 4w change | M29: z-score vs 2y | N29: On release (verify day/lag) | O29: Usable only from actual publication timestamp + buffer; never align to reference date. | P29: 0 | Q29: 1 | R29: 1 | S29: 0 | T29: 0 | U29: P1 | V29: Crowding / reversal signal; one of the best public COP flow series
A30: PF-03 | B30: PF Positioning & flows | C30: COP pension fund positions | D30: AFP net forward USD position | E30: COP | F30: =IF(E30="ALL",3,IF(E30="Global",1,LEN(E30)-LEN(SUBSTITUTE(E30,",",""))+1)) -> 1 | G30: 2 | H30: =F30*G30 -> 2 | I30: BanRep / Superfinanciera | J30: Weekly/Monthly | K30: 1d | L30: Level; change | M30: z-score | N30: On release | O30: Usable only from actual publication timestamp + buffer; never align to reference date. | P30: 0 | Q30: 1 | R30: 1 | S30: 0 | T30: 0 | U30: P2
A31: PF-04 | B31: PF Positioning & flows | C31: PEN pension fund flows | D31: AFP FX position and asset sales; withdrawal (retiro) payouts | E31: PEN | F31: =IF(E31="ALL",3,IF(E31="Global",1,LEN(E31)-LEN(SUBSTITUTE(E31,",",""))+1)) -> 1 | G31: 3 | H31: =F31*G31 -> 3 | I31: BCRP, SBS | J31: Weekly/Monthly | K31: 1d | L31: Position; 4w change; withdrawal event flag | M31: z-score | N31: On release | O31: Usable only from actual publication timestamp + buffer; never align to reference date. | P31: 0 | Q31: 1 | R31: 1 | S31: 0 | T31: 0 | U31: P1 | V31: Withdrawal laws forced large AFP USD sales
A32: PF-05 | B32: PF Positioning & flows | C32: PEN dollarization | D32: Share of deposits/credit in USD; change | E32: PEN | F32: =IF(E32="ALL",3,IF(E32="Global",1,LEN(E32)-LEN(SUBSTITUTE(E32,",",""))+1)) -> 1 | G32: 2 | H32: =F32*G32 -> 2 | I32: BCRP | J32: Monthly | K32: 1d | L32: Level; 3m change | M32: None | N32: On release | O32: Usable only from actual publication timestamp + buffer; never align to reference date. | P32: 0 | Q32: 1 | R32: 1 | S32: 0 | T32: 0 | U32: P3 | V32: Slow structural demand for USD
A33: PF-06 | B33: PF Positioning & flows | C33: Local corporate / bank FX demand | D33: Banks' spot + forward FX position; corporate forward purchases | E33: ALL | F33: =IF(E33="ALL",3,IF(E33="Global",1,LEN(E33)-LEN(SUBSTITUTE(E33,",",""))+1)) -> 3 | G33: 2 | H33: =F33*G33 -> 6 | I33: BCCh formal FX market, BanRep, BCRP | J33: Daily/Weekly | K33: 1d | L33: Level; 5d change | M33: z-score | N33: On release | O33: Usable only from actual publication timestamp + buffer; never align to reference date. | P33: 0 | Q33: 0 | R33: 1 | S33: 0 | T33: 0 | U33: P2
A34: PF-07 | B34: PF Positioning & flows | C34: Mining & oil export flows | D34: Export receipts proxy: copper export values (CLP, PEN), oil exports (COP) | E34: ALL | F34: =IF(E34="ALL",3,IF(E34="Global",1,LEN(E34)-LEN(SUBSTITUTE(E34,",",""))+1)) -> 3 | G34: 1 | H34: =F34*G34 -> 3 | I34: Customs / CB trade stats | J34: Monthly | K34: 1d | L34: 3m change | M34: z-score | N34: On release | O34: Usable only from actual publication timestamp + buffer; never align to reference date. | P34: 0 | Q34: 1 | R34: 1 | S34: 0 | T34: 0 | U34: P3
A35: PF-08 | B35: PF Positioning & flows | C35: EM fund flows | D35: Country bond and equity fund flows | E35: ALL | F35: =IF(E35="ALL",3,IF(E35="Global",1,LEN(E35)-LEN(SUBSTITUTE(E35,",",""))+1)) -> 3 | G35: 2 | H35: =F35*G35 -> 6 | I35: EPFR (paid) | J35: Weekly | K35: 1d | L35: 4w sum | M35: z-score | N35: On release | O35: Usable only from actual publication timestamp + buffer; never align to reference date. | P35: 0 | Q35: 0 | R35: 1 | S35: 0 | T35: 0 | U35: P3 | V35: Optional if budget allows
A36: CB-01 | B36: CB Central bank & intervention | C36: BCRP intervention (spot) | D36: Net BCRP spot USD sales(-)/purchases(+) in interbank market, USD mn | E36: PEN | F36: =IF(E36="ALL",3,IF(E36="Global",1,LEN(E36)-LEN(SUBSTITUTE(E36,",",""))+1)) -> 1 | G36: 3 | H36: =F36*G36 -> 3 | I36: BCRP daily operations | J36: 1d | K36: 1d | L36: Day; 5d sum; 20d sum | M36: Scale by 20d ADV | N36: Same day, after operations (verify time) | O36: Usable only from actual publication timestamp + buffer; never align to reference date. | P36: 0 | Q36: 1 | R36: 1 | S36: 1 | T36: 0 | U36: P1 | V36: The core PEN signal: BCRP smooths moves, so intervention reveals pressure
A37: CB-02 | B37: CB Central bank & intervention | C37: BCRP intervention (derivatives) | D37: Net new placement of FX swaps (swaps cambiarios), CDR-type instruments, USD mn | E37: PEN | F37: =IF(E37="ALL",3,IF(E37="Global",1,LEN(E37)-LEN(SUBSTITUTE(E37,",",""))+1)) -> 1 | G37: 3 | H37: =F37*G37 -> 3 | I37: BCRP daily operations | J37: 1d | K37: 1d | L37: Day; 5d sum; outstanding stock | M37: Scale by ADV | N37: Same day (verify time) | O37: Usable only from actual publication timestamp + buffer; never align to reference date. | P37: 0 | Q37: 1 | R37: 1 | S37: 1 | T37: 0 | U37: P1 | V37: Verify instrument names against current BCRP releases
A38: CB-03 | B38: CB Central bank & intervention | C38: BCRP intervention probability target | D38: P(BCRP intervenes tomorrow) from a separate classifier | E38: PEN | F38: =IF(E38="ALL",3,IF(E38="Global",1,LEN(E38)-LEN(SUBSTITUTE(E38,",",""))+1)) -> 1 | G38: 1 | H38: =F38*G38 -> 1 | I38: Model output | J38: 1d | K38: 1d | M38: logit | N38: After model run | O38: Value as of the daily decision snapshot; if source updates after it, use prior snapshot. | P38: 0 | Q38: 1 | R38: 1 | S38: 0 | T38: 0 | U38: P2 | V38: Also a target; see Targets tab
A39: CB-04 | B39: CB Central bank & intervention | C39: BCCh FX program | D39: Program active flag; daily spot sales/swaps executed | E39: CLP | F39: =IF(E39="ALL",3,IF(E39="Global",1,LEN(E39)-LEN(SUBSTITUTE(E39,",",""))+1)) -> 1 | G39: 2 | H39: =F39*G39 -> 2 | I39: BCCh announcements & statistics | J39: Event/1d | K39: 1d | L39: Flag; 5d cumulative | M39: Scale by ADV | N39: At announcement / publication time | O39: Usable only from actual publication timestamp + buffer; never align to reference date. | P39: 0 | Q39: 1 | R39: 1 | S39: 1 | T39: 0 | U39: P1 | V39: Programs in 2019, 2022 etc.; rare but decisive
A40: CB-05 | B40: CB Central bank & intervention | C40: BanRep FX operations | D40: Reserve accumulation auctions, FX swaps/NDF auctions | E40: COP | F40: =IF(E40="ALL",3,IF(E40="Global",1,LEN(E40)-LEN(SUBSTITUTE(E40,",",""))+1)) -> 1 | G40: 2 | H40: =F40*G40 -> 2 | I40: BanRep announcements | J40: Event | K40: 1d | L40: Flag; 20d cumulative | M40: Scale by ADV | N40: At announcement time | O40: Usable only from actual publication timestamp + buffer; never align to reference date. | P40: 0 | Q40: 1 | R40: 1 | S40: 0 | T40: 0 | U40: P2
...

Sheet Targets
A1: Horizon | B1: Bar freq | C1: Return target | D1: Direction target | E1: Volatility target | F1: Tail target | G1: Purge / embargo | H1: Primary models | I1: Notes
A2: 1h | B2: 1h | C2: Fwd return next 1 bar / sigma_1h (local session only) | D2: Sign with dead zone ±0.25 sigma | E2: log RV next 4h | F2: P(|r| > 2 sigma_1h) | G2: Purge 1 bar; embargo 1 session | H2: PatchTST, EXE | I2: Mostly for execution timing; thin outside local hours
A3: 1d | B3: 1d | C3: Snapshot-to-snapshot return / sigma_20d | D3: Triple barrier ±1.5 sigma_d, 1d timeout, net of cost | E3: log RV next day | F3: P(|r| > 2 sigma_d) | G3: Purge 1d; embargo 5d | H3: XGB, TFT, PatchTST | I3: Main alpha target
A4: 5d | B4: 1d | C4: 5d fwd return / sigma_5d | D4: Triple barrier ±1.5 sigma, 5d timeout, net of cost | E4: log RV next 5d | F4: P(max adverse move > 2 sigma_5d) | G4: Purge 5d; embargo 10d | H4: XGB, TFT | I4: Overlapping labels: use sample-uniqueness weights
A5: 20d | B5: 1d | C5: 20d fwd return / sigma_20d | D5: Sign, net of carry | E5: log RV next 20d | F5: P(|r| > 2 sigma_20d) | G5: Purge 20d; embargo 20d | H5: TFT, XGB | I5: ~190 independent obs per ccy over 15y; weight lightly
A6: 1d (PEN) | B6: 1d | C6: PEN move beyond intervention: r_d - beta × scaled BCRP net sales | D6: P(BCRP intervenes next day) | E6: — | F6: P(|r| > 2 sigma) given intervention | G6: Purge 1d; embargo 5d | H6: XGB | I6: Auxiliary targets: model the central bank, not just price

Sheet Models
A1: Model | B1: Role | C1: Frequency | D1: Inputs (blocks) | E1: Lookback | F1: Outputs | G1: Starting hyperparameters | H1: Notes
A2: Ridge baseline | B2: Benchmark every model must beat | C2: 1d | D2: CR, PX momentum, CM residual, PF, CB | E2: 20-120d features | F2: 1d, 5d return | G2: alpha by CV; standardized inputs | H2: If a deep model can't beat this net of cost, drop it
A3: LightGBM / XGBoost | B3: Nonlinear daily workhorse | C3: 1d | D3: All daily blocks | E3: Via features | F3: Return, direction, vol, tail; BCRP intervention prob. | G3: depth 3-5, lr 0.02, early stopping, colsample 0.5, min_data_in_leaf 150 | H3: Pooled across CLP/COP/PEN with ccy ID; add helper ccys (BRL, MXN, ZAR, AUD) as extra rows with a flag
A4: PatchTST | B4: Hourly sequence model | C4: 1h | D4: PX, GL (incl. BRL/MXN lead), CM, CAL, TX | E4: 336 bars (≈14 days) | F4: 1h, 1d return + vol | G4: patch 16, stride 8, d_model 64, 2 layers, 4 heads, channel-independent | H4: Pool with helper ccys; data too thin otherwise. Mamba is a fair challenger here with longer lookbacks
A5: Temporal Fusion Transformer | B5: Daily macro model | C5: 1d | D5: All daily blocks; CAL & PO as known-future; ccy as static | E5: 120d encoder, 20d decoder | F5: Quantiles 0.1/0.5/0.9 for 1-20d | G5: hidden 32-64, 4 heads, dropout 0.3, lr 1e-3 | H5: Keep small: ~11k rows. Only keep if it adds alpha over LightGBM
A6: Spanish text model | B6: Feature generator | C6: Event / 1h | D6: CB statements, local press, wires | E6: Per document | F6: Tone, fiscal-risk, political-risk scores | G6: Fine-tuned XLM-R / BETO, or LLM extraction with fixed prompt | H6: Feeds TX block; freeze version per backtest window
A7: HMM regime | B7: Regime / risk gate | C7: 1d | D7: VIX z, EM corr, RR z, RV, CDS z | E7: Fit on training window | F7: 5 filtered state probs | G7: Gaussian HMM, 5 states (drop to 3-4 if unstable) | H7: Scales gross exposure in risk-off
A8: Execution scheduler | B8: When to trade after the signal | C8: 1h / quotes | D8: CAL session flags, fixing deviation, liquidity regime | E8: 20d | F8: Expected cost by time slot | G8: Rule-based first; learn from your own fills later | H8: No public order book: learn from dealer quotes and TCA
A9: Meta-weighter | B9: Blend model forecasts | C9: 1d | D9: Regime probs, dispersion, rolling IC | E9: 60d | F9: Model weights | G9: Regime-conditioned weights shrunk 50%+ toward equal weight | H9: Guards against chasing recent performance

Sheet Currency Notes
A1: Currency | B1: Main instruments | C1: Price discovery | D1: Fixing | E1: Key local drivers | F1: Est. cost normal (bps RT) | G1: Est. cost stress (bps RT) | H1: Stress ratio | I1: Special risks
A2: CLP | B2: Onshore spot (Datatec); offshore NDF; cámara swaps; CLP options (reasonable liquidity) | C2: Onshore spot in local hours; NDF otherwise | D2: Dólar observado (BCCh; set from prior day's trades) | E2: Copper, China, AFP hedging, BCCh, DXY | F2: 6 | G2: 25 | H2: =IF(F2=0,0,G2/F2) -> 4.1666667 | I2: AFP hedge-ratio shifts, BCCh programs, social/constitutional unrest (2019)
A3: COP | B3: Onshore spot (SET-FX); offshore NDF; IBR/TES; COP options | C3: Onshore spot in local hours; NDF otherwise | D3: TRM (from prior day's trades) | E3: Oil, fiscal/political news, offshore NDF positioning, TES flows, BanRep | F3: 9 | G3: 40 | H3: =IF(F3=0,0,G3/F3) -> 4.4444444 | I3: Fiscal-rule changes, political risk, thin liquidity, wide stress spreads
A4: PEN | B4: Onshore interbank spot (Datatec); offshore NDF; sovereign bonds; very thin options | C4: Onshore spot; BCRP highly active | D4: BCRP reference rate / SBS rate | E4: Copper & gold, BCRP intervention, AFP withdrawals, politics | F4: 10 | G4: 45 | H4: =IF(F4=0,0,G4/F4) -> 4.5 | I4: Heavy BCRP smoothing hides risk, then gaps; political crises; pension-withdrawal laws
A6: Costs are illustrative round-trip guesses for 1M NDFs (blue = editable), not measured. Replace with dealer quotes and your own TCA.

Sheet Data Sources
A1: Source | B1: Covers | C1: Access | D1: Frequency | E1: Timestamp notes
A2: BCCh statistics API (SIETE) | B2: Dólar observado, rates, AFP/derivatives positions, reserves, intervention | C2: Free; registration for API user/password | D2: Daily / weekly / monthly | E2: API gives values by reference date only: publication time must be assigned by rule (see pipeline config)
A3: BCRP statistics API | B3: Interbank FX rate, daily FX operations (spot, swaps, CDR), reserves, rates, dollarization | C3: Free; no key | D3: Daily / monthly | E3: Same: assign publication time by rule; daily operations published same day
A4: BanRep / datos.gov.co | B4: TRM (Socrata API); derivatives positions (offshore agents, AFPs); FX auctions; reserves | C4: Free; TRM via API, derivatives often Excel downloads | D4: Daily / weekly | E4: Derivatives files loaded via file loader; record download time as vintage
A5: Superintendencias / SBS / Superfinanciera | B5: Pension-fund portfolios & FX exposure | C5: Free; files | D5: Monthly | E5: Publication lag weeks
A6: Dealer NDF quotes / Bloomberg / LSEG | B6: NDF curves, onshore spot history, vol surfaces, CDS, ECO consensus | C6: Paid | D6: Intraday / daily | E6: Export at a fixed snapshot time; load via CSV loader
A7: Datatec / SET-FX | B7: Onshore spot trades for CLP/PEN (Datatec) and COP (SET-FX) | C7: Paid, often via local broker | D7: Tick / intraday | E7: Local-time timestamps: convert to UTC
A8: FRED / US Treasury | B8: UST yields, SOFR, DXY proxies | C8: Free | D8: Daily | E8: Release times well documented
A9: LME / COMEX / ICE | B9: Copper, gold, zinc, Brent, coffee | C9: Paid (delayed free via FRED/others) | D9: Daily / intraday | E9: Different session closes: align on availability
A10: Electoral authorities & polls | B10: SERVEL (CL), Registraduría (CO), JNE/ONPE (PE); poll aggregators | C10: Free | D10: Event / weekly | E10: Use poll publication date, not fieldwork date
A11: Local press & wires | B11: El Mercurio, Diario Financiero, Portafolio, La República, Gestión, El Comercio; Bloomberg/Reuters | C11: Mixed | D11: Real time | E11: First-seen timestamp; ignore later edits

Sheet Stress Episodes
A1: Episode | B1: Window | C1: Currencies | D1: Why it matters
A2: 2013 taper tantrum | B2: May-Sep 2013 | C2: All | D2: Global USD shock; tests carry crash behavior
A3: 2014-16 commodity crash | B3: Jul 2014-Jan 2016 | C3: All (COP worst) | D3: Oil collapse hit COP; copper slide hit CLP/PEN
A4: Chile social unrest (estallido) | B4: Oct-Dec 2019 | C4: CLP | D4: Record CLP highs, then BCCh USD 20bn intervention program
A5: COVID shock | B5: Feb-Apr 2020 | C5: All | D5: Liquidity crisis; spreads blew out
A6: Chile pension withdrawals & constitution | B6: 2020-2023 | C6: CLP | D6: AFP asset sales; constitutional processes
A7: Peru 2021 election | B7: Apr-Jul 2021 | C7: PEN | D7: Sharp PEN selloff, heavy BCRP intervention
A8: Peru Castillo crisis | B8: Dec 2022 | C8: PEN | D8: Self-coup attempt and removal; test gap behavior
A9: Colombia 2022 election & fiscal | B9: May-Nov 2022 | C9: COP | D9: Record COP weakness; fiscal/policy uncertainty
A10: Colombia fiscal-rule stress | B10: 2024-2025 | C10: COP | D10: Fiscal slippage and rule changes; TES selloffs
A11: 2025-26 election cycles | B11: Chile 2025; Peru & Colombia 2026 | C11: All | D11: Recent regime; use as final out-of-sample check

Sheet Roadmap
A1: Step | B1: Workstream | C1: Timing | D1: What to do | E1: Deliverable
A2: 1 | B2: Trading setup | C2: Week 1 | D2: Pick instruments (offshore 1M NDFs), counterparties/ISDA, snapshot time, capacity. Get dealer spreads in normal and stressed markets. | E2: Signed-off trading setup; first real cost numbers
A3: 2 | B3: Point-in-time data layer | C3: Weeks 1-6 | D3: Run the andeanfx pipeline for BCCh, BCRP, BanRep; load vendor NDF/vol exports; verify every series code and publication rule. | E3: Daily as-of panel for CLP/COP/PEN back to ~2010
A4: 3 | B4: Andean features (P1) | C4: Weeks 4-8 | D4: Implement P1 features: carry, momentum, commodity residuals, BCRP intervention, COP offshore positioning, AFP flows, political calendar. | E4: Feature store with leakage tests
A5: 4 | B5: Baseline + harness | C5: Weeks 6-10 | D5: Purged walk-forward, cost model, ridge and LightGBM, stress-episode report. | E5: Net-of-cost baseline Sharpe and IC
A6: 5 | B6: Text + sequence model | C6: Weeks 10-16 | D6: Spanish CB/politics text scores; pooled PatchTST/TFT with helper currencies; incremental-alpha test. | E6: Keep/drop decision per model
A7: 6 | B7: Paper trade | C7: Months 4-7 | D7: Run live at the snapshot with dealer quotes; measure slippage vs model. | E7: 3 months of live-signal track record
A8: 7 | B8: Go live small | C8: Month 7+ | D8: Trade ~20% of target size; scale only if live costs and hit rates match backtest. | E8: Production system
